Internal Server Error: /recursoshumanos/solicitar-horas-samic/
Traceback (most recent call last):
  File "C:\virtual_h\Lib\site-packages\django\core\handlers\exception.py", line 55, in inner
    response = get_response(request)
  File "C:\virtual_h\Lib\site-packages\django\core\handlers\base.py", line 197, in _get_response
    response = wrapped_callback(request, *callback_args, **callback_kwargs)
  File "C:\virtual_h\Lib\site-packages\django\contrib\auth\decorators.py", line 59, in _view_wrapper
    return view_func(request, *args, **kwargs)
  File "C:\virtual_h\proyecto_01\recursos_humanos\views.py", line 27, in solicitar_horas_samic
    if form.is_valid():
       ~~~~~~~~~~~~~^^
  File "C:\virtual_h\Lib\site-packages\django\forms\forms.py", line 206, in is_valid
    return self.is_bound and not self.errors
                                 ^^^^^^^^^^^
  File "C:\virtual_h\Lib\site-packages\django\forms\forms.py", line 201, in errors
    self.full_clean()
    ~~~~~~~~~~~~~~~^^
  File "C:\virtual_h\Lib\site-packages\django\forms\forms.py", line 338, in full_clean
    self._clean_form()
    ~~~~~~~~~~~~~~~~^^
  File "C:\virtual_h\Lib\site-packages\django\forms\forms.py", line 354, in _clean_form
    cleaned_data = self.clean()
  File "C:\virtual_h\proyecto_01\recursos_humanos\forms.py", line 32, in clean
    if fecha_hora_hasta <= fecha_hora_desde:
       ^^^^^^^^^^^^^^^^^^^^^^^^^^^^^^^^^^^^
TypeError: '<=' not supported between instances of 'datetime.date' and 'datetime.datetime'
"POST /recursoshumanos/solicitar-horas-samic/ HTTP/1.1" 500 91148
Internal Server Error: /recursoshumanos/solicitar-horas-samic/
Traceback (most recent call last):
  File "C:\virtual_h\Lib\site-packages\django\core\handlers\exception.py", line 55, in inner
    response = get_response(request)
  File "C:\virtual_h\Lib\site-packages\django\core\handlers\base.py", line 197, in _get_response
    response = wrapped_callback(request, *callback_args, **callback_kwargs)
  File "C:\virtual_h\Lib\site-packages\django\contrib\auth\decorators.py", line 59, in _view_wrapper
    return view_func(request, *args, **kwargs)
  File "C:\virtual_h\proyecto_01\recursos_humanos\views.py", line 27, in solicitar_horas_samic
    if form.is_valid():
       ~~~~~~~~~~~~~^^
  File "C:\virtual_h\Lib\site-packages\django\forms\forms.py", line 206, in is_valid
    return self.is_bound and not self.errors
                                 ^^^^^^^^^^^
  File "C:\virtual_h\Lib\site-packages\django\forms\forms.py", line 201, in errors
    self.full_clean()
    ~~~~~~~~~~~~~~~^^
  File "C:\virtual_h\Lib\site-packages\django\forms\forms.py", line 338, in full_clean
    self._clean_form()
    ~~~~~~~~~~~~~~~~^^
  File "C:\virtual_h\Lib\site-packages\django\forms\forms.py", line 354, in _clean_form
    cleaned_data = self.clean()
  File "C:\virtual_h\proyecto_01\recursos_humanos\forms.py", line 32, in clean
    if fecha_hora_desde <= now:
       ^^^^^^^^^^^^^^^^^^^^^^^
TypeError: can't compare offset-naive and offset-aware datetimes
"POST /recursoshumanos/solicitar-horas-samic/ HTTP/1.1" 500 91203
Internal Server Error: /recursoshumanos/solicitar-horas-samic/
Traceback (most recent call last):
  File "C:\virtual_h\Lib\site-packages\django\core\handlers\exception.py", line 55, in inner
    response = get_response(request)
  File "C:\virtual_h\Lib\site-packages\django\core\handlers\base.py", line 197, in _get_response
    response = wrapped_callback(request, *callback_args, **callback_kwargs)
  File "C:\virtual_h\Lib\site-packages\django\contrib\auth\decorators.py", line 59, in _view_wrapper
    return view_func(request, *args, **kwargs)
  File "C:\virtual_h\proyecto_01\recursos_humanos\views.py", line 27, in solicitar_horas_samic
    if form.is_valid():
       ~~~~~~~~~~~~~^^
  File "C:\virtual_h\Lib\site-packages\django\forms\forms.py", line 206, in is_valid
    return self.is_bound and not self.errors
                                 ^^^^^^^^^^^
  File "C:\virtual_h\Lib\site-packages\django\forms\forms.py", line 201, in errors
    self.full_clean()
    ~~~~~~~~~~~~~~~^^
  File "C:\virtual_h\Lib\site-packages\django\forms\forms.py", line 338, in full_clean
    self._clean_form()
    ~~~~~~~~~~~~~~~~^^
  File "C:\virtual_h\Lib\site-packages\django\forms\forms.py", line 354, in _clean_form
    cleaned_data = self.clean()
  File "C:\virtual_h\proyecto_01\recursos_humanos\forms.py", line 32, in clean
    now = timezone.now()
          ^^^^^^^^^^^^
AttributeError: type object 'datetime.timezone' has no attribute 'now'
"POST /recursoshumanos/solicitar-horas-samic/ HTTP/1.1" 500 91071
